Workbook

Sheet README
A1: ETF Intelligence Agent - Master Template
A3: Obiettivo
A4: Questo file definisce la struttura dati, le categorie, il modello di scoring e il report giornaliero per un agente che analizza ETF quotati su Borsa Italiana/ETFplus. Non fornisce consulenza finanziaria personalizzata: produce shortlist e segnali da valutare.
A8: Fogli | B8: Descrizione
A9: ETF_Master | B9: Database principale ETF, metriche e punteggi
A10: Scoring_Model | B10: Pesi e regole del modello
A11: Macro_Geopolitica | B11: Valutazione scenario macro/geopolitico
A12: Daily_Report | B12: Template del report giornaliero
A13: Sources | B13: Fonti dati da usare
A14: Lists | B14: Liste per menu a tendina

Sheet Lists
A1: Categoria | B1: Stato | C1: Classe Asset | D1: Replica | E1: Distribuzione | F1: Rischio Tema | G1: Macro Bias
A2: Core | B2: Buy Watchlist | C2: Equity | D2: Fisica | E2: Accumulazione | F2: Basso | G2: Favorevole
A3: Thematic Growth | B3: Accumulate Carefully | C3: Bond | D3: Sintetica | E3: Distribuzione | F3: Medio | G3: Neutrale
A4: Defensive | B4: Hold / Monitor | C4: Commodity | D4: Campionamento | E4: N/A | F4: Alto | G4: Sfavorevole
A5: Factor | B5: Avoid for Now | C5: Money Market | D5: N/A | F5: Molto alto
A6: Geographic/Satellite | B6: Speculative Only | C6: Mixed

Sheet Scoring_Model
A1: Modello di scoring ETF
A3: Area | B3: Peso | C3: Descrizione | D3: Input/Formula | E3: Interpretazione | F3: Note
A4: Momentum 6/12 mesi | B4: 0.2 | C4: Forza relativa recente | D4: Ranking percentile su momentum | E4: Più alto è meglio | F4: Da Meb Faber / trend following
A5: Rendimento storico ponderato | B5: 0.15 | C5: CAGR e performance storica pesata per lunghezza storico | D5: CAGR * affidabilità storico | E5: Più alto è meglio | F5: Non esclude ETF giovani
A6: Rischio | B6: 0.2 | C6: Volatilità e max drawdown | D6: Punteggio rischio inverso | E6: Più basso il rischio, più alto il punteggio | F6: Marks/Taleb: preservare capitale
A7: Qualità ETF | B7: 0.15 | C7: TER, liquidità, dimensione fondo | D7: Score qualità | E7: Più alto è meglio | F7: Bogle: costi bassi e liquidità
A8: Forza tema | B8: 0.15 | C8: AI, semiconduttori, difesa, healthcare, ecc. | D8: Valutazione 0-100 | E8: Più alto è meglio | F8: Input qualitativo aggiornabile
A9: Macro/geopolitica | B9: 0.1 | C9: Scenario tassi, inflazione, geopolitica, ciclo | D9: Valutazione -20/+20 normalizzata | E9: Favorevole/sfavorevole | F9: Da aggiornare nel foglio Macro_Geopolitica
A10: Penalità | B10: -0.05 | C10: Euforia, concentrazione, rischio moda | D10: 0/-5/-10/-15 | E10: Più negativa = più rischio | F10: Evita bolle e crowded trade

Sheet Macro_Geopolitica
A1: Scenario macro/geopolitico - input qualitativi
A3: Fattore | B3: Stato attuale | C3: Impatto | D3: Asset/temi favoriti | E3: Asset/temi penalizzati | F3: Punteggio | G3: Fonte | H3: Note
A4: Tassi di interesse | B4: Da aggiornare | C4: Neutrale | D4: Money market, bond short duration | E4: Growth long duration | F4: 0
A5: Inflazione | B5: Da aggiornare | C5: Neutrale | D5: Gold, inflation linked | E5: Bond lunga durata | F5: 0
A6: Ciclo economico | B6: Da aggiornare | C6: Neutrale | D6: Quality, defensive | E6: Small cap cicliche | F6: 0
A7: AI / semiconduttori | B7: Da aggiornare | C7: Neutrale | D7: AI, semiconductor, Nasdaq | E7: Settori value tradizionali | F7: 0 | H7: Controllare rischio concentrazione
A8: Geopolitica difesa | B8: Da aggiornare | C8: Neutrale | D8: Defence, cyber, gold | E8: Emerging sensibili | F8: 0
A9: USA/Cina/Taiwan | B9: Da aggiornare | C9: Neutrale | D9: Diversificazione globale | E9: Semiconduttori concentrati | F9: 0
A10: Energia/commodities | B10: Da aggiornare | C10: Neutrale | D10: Energy, commodities | E10: Settori energivori | F10: 0

Sheet ETF_Master
A1: Ticker | B1: ISIN | C1: Nome ETF | D1: Categoria | E1: Classe Asset | F1: Tema/Area | G1: Benchmark | H1: Valuta | I1: Replica | J1: Distribuzione | K1: TER % | L1: AUM mln | M1: Volume medio | N1: Data lancio | O1: Anni storico | P1: Prezzo | Q1: MA50 | R1: MA200 | S1: Trend OK | T1: Rendimento 1M % | U1: Rendimento 3M % | V1: Rendimento 6M % | W1: Rendimento 12M % | X1: CAGR storico % | Y1: Volatilità % | Z1: Max Drawdown % | AA1: Sharpe | AB1: Momentum Score | AC1: Storico Score | AD1: Risk Score | AE1: Qualità ETF Score | AF1: Tema Score | AG1: Macro Score | AH1: Penalità | AI1: Score Finale | AJ1: Stato | AK1: Note AI | AL1: Fonte dati
A2: VWCE.MI | C2: Vanguard FTSE All-World UCITS ETF | D2: Core | F2: Global Equity
A3: SWDA.MI | C3: iShares Core MSCI World UCITS ETF | D3: Core | F3: Global Equity
A4: VUAA.MI | C4: Vanguard S&P 500 UCITS ETF | D4: Core | F4: USA Large Cap
A5: EQQQ.MI | C5: Invesco Nasdaq-100 UCITS ETF | D5: Core | F5: Nasdaq / Tech
A6: EXSA.MI | C6: iShares STOXX Europe 600 UCITS ETF | D6: Core | F6: Europe
A7: EIMI.MI | C7: iShares Core MSCI Emerging Markets IMI UCITS ETF | D7: Core | F7: Emerging Markets
A8: AGGH.MI | C8: iShares Core Global Aggregate Bond UCITS ETF | D8: Defensive | F8: Global Bonds
A9: VAGF.MI | C9: Vanguard Global Aggregate Bond UCITS ETF | D9: Defensive | F9: Global Bonds
A10: SGLD.MI | C10: Invesco Physical Gold ETC | D10: Defensive | F10: Gold
A11: IWQU.MI | C11: iShares MSCI World Quality Factor UCITS ETF | D11: Factor | F11: Quality
A12: IWMO.MI | C12: iShares MSCI World Momentum Factor UCITS ETF | D12: Factor | F12: Momentum
A13: XDEV.MI | C13: Xtrackers MSCI World Value UCITS ETF | D13: Factor | F13: Value
... A21: FGQI.MI | C21: Fidelity Global Quality Income UCITS ETF | D21: Satellite | F21: Quality Dividend

Sheet Daily_Report
A1: Report giornaliero - ETF Intelligence Agent
A3: Data report | B3: 46166.95
A4: Scenario mercato | B4: Da aggiornare
A5: Rischio generale | B5: Basso / Medio / Alto
A6: Bias operativo | B6: Core / Thematic / Defensive / Cash
A7: Nota | B7: Il report produce shortlist, non raccomandazioni personalizzate.
A10: Top 10 ETF assoluti
A11: Rank | B11: Ticker | C11: Nome ETF | D11: Categoria | E11: Tema | F11: Score | G11: Stato | H11: Note AI
A12: {=SEQUENCE(10)} | B12: =IFERROR(INDEX(SORTBY(FILTER(ETF_Master!A:AK,ETF_Master!AI:AI<>""),FILTER(ETF_Master!AI:AI,ETF_Master!AI:AI<>""),-1),ROW(A1),{1,3,4,6,35,36,37}),"")
A13: 2 | B13: =IFERROR(INDEX(SORTBY(FILTER(ETF_Master!A:AK,ETF_Master!AI:AI<>""),FILTER(ETF_Master!AI:AI,ETF_Master!AI:AI<>""),-1),ROW(A1),{1,3,4,6,35,36,37}),"")
A14: 3 | B14: =IFERROR(INDEX(SORTBY(FILTER(ETF_Master!A:AK,ETF_Master!AI:AI<>""),FILTER(ETF_Master!AI:AI,ETF_Master!AI:AI<>""),-1),ROW(A1),{1,3,4,6,35,36,37}),"")
A15: 4 | B15: =IFERROR(INDEX(SORTBY(FILTER(ETF_Master!A:AK,ETF_Master!AI:AI<>""),FILTER(ETF_Master!AI:AI,ETF_Master!AI:AI<>""),-1),ROW(A1),{1,3,4,6,35,36,37}),"")
A16: 5 | B16: =IFERROR(INDEX(SORTBY(FILTER(ETF_Master!A:AK,ETF_Master!AI:AI<>""),FILTER(ETF_Master!AI:AI,ETF_Master!AI:AI<>""),-1),ROW(A1),{1,3,4,6,35,36,37}),"")
A17: 6 | B17: =IFERROR(INDEX(SORTBY(FILTER(ETF_Master!A:AK,ETF_Master!AI:AI<>""),FILTER(ETF_Master!AI:AI,ETF_Master!AI:AI<>""),-1),ROW(A1),{1,3,4,6,35,36,37}),"")
A18: 7 | B18: =IFERROR(INDEX(SORTBY(FILTER(ETF_Master!A:AK,ETF_Master!AI:AI<>""),FILTER(ETF_Master!AI:AI,ETF_Master!AI:AI<>""),-1),ROW(A1),{1,3,4,6,35,36,37}),"")
A19: 8 | B19: =IFERROR(INDEX(SORTBY(FILTER(ETF_Master!A:AK,ETF_Master!AI:AI<>""),FILTER(ETF_Master!AI:AI,ETF_Master!AI:AI<>""),-1),ROW(A1),{1,3,4,6,35,36,37}),"")
A20: 9 | B20: =IFERROR(INDEX(SORTBY(FILTER(ETF_Master!A:AK,ETF_Master!AI:AI<>""),FILTER(ETF_Master!AI:AI,ETF_Master!AI:AI<>""),-1),ROW(A1),{1,3,4,6,35,36,37}),"")
A21: 10 | B21: =IFERROR(INDEX(SORTBY(FILTER(ETF_Master!A:AK,ETF_Master!AI:AI<>""),FILTER(ETF_Master!AI:AI,ETF_Master!AI:AI<>""),-1),ROW(A1),{1,3,4,6,35,36,37}),"")
A23: Top 5 Core
A24: Rank | B24: Ticker | C24: Nome ETF | D24: Categoria | E24: Tema | F24: Score | G24: Stato | H24: Note AI
A25: {=SEQUENCE(5)} | B25: =IFERROR(INDEX(SORTBY(FILTER(ETF_Master!A:AK,ETF_Master!D:D="Core"),FILTER(ETF_Master!AI:AI,ETF_Master!D:D="Core"),-1),ROW(A1),{1,3,4,6,35,36,37}),"")
A26: 2 | B26: =IFERROR(INDEX(SORTBY(FILTER(ETF_Master!A:AK,ETF_Master!D:D="Core"),FILTER(ETF_Master!AI:AI,ETF_Master!D:D="Core"),-1),ROW(A1),{1,3,4,6,35,36,37}),"")
A27: 3 | B27: =IFERROR(INDEX(SORTBY(FILTER(ETF_Master!A:AK,ETF_Master!D:D="Core"),FILTER(ETF_Master!AI:AI,ETF_Master!D:D="Core"),-1),ROW(A1),{1,3,4,6,35,36,37}),"")
A28: 4 | B28: =IFERROR(INDEX(SORTBY(FILTER(ETF_Master!A:AK,ETF_Master!D:D="Core"),FILTER(ETF_Master!AI:AI,ETF_Master!D:D="Core"),-1),ROW(A1),{1,3,4,6,35,36,37}),"")
A29: 5 | B29: =IFERROR(INDEX(SORTBY(FILTER(ETF_Master!A:AK,ETF_Master!D:D="Core"),FILTER(ETF_Master!AI:AI,ETF_Master!D:D="Core"),-1),ROW(A1),{1,3,4,6,35,36,37}),"")
A32: Top 5 Tematici
A33: Rank | B33: Ticker | C33: Nome ETF | D33: Categoria | E33: Tema | F33: Score | G33: Stato | H33: Note AI
A34: {=SEQUENCE(5)} | B34: =IFERROR(INDEX(SORTBY(FILTER(ETF_Master!A:AK,ETF_Master!D:D="Thematic Growth"),FILTER(ETF_Master!AI:AI,ETF_Master!D:D="Thematic Growth"),-1),ROW(A1),{1,3,4,6,35,36,37}),"")
A35: 2 | B35: =IFERROR(INDEX(SORTBY(FILTER(ETF_Master!A:AK,ETF_Master!D:D="Thematic Growth"),FILTER(ETF_Master!AI:AI,ETF_Master!D:D="Thematic Growth"),-1),ROW(A1),{1,3,4,6,35,36,37}),"")
A36: 3 | B36: =IFERROR(INDEX(SORTBY(FILTER(ETF_Master!A:AK,ETF_Master!D:D="Thematic Growth"),FILTER(ETF_Master!AI:AI,ETF_Master!D:D="Thematic Growth"),-1),ROW(A1),{1,3,4,6,35,36,37}),"")
A37: 4 | B37: =IFERROR(INDEX(SORTBY(FILTER(ETF_Master!A:AK,ETF_Master!D:D="Thematic Growth"),FILTER(ETF_Master!AI:AI,ETF_Master!D:D="Thematic Growth"),-1),ROW(A1),{1,3,4,6,35,36,37}),"")
A38: 5 | B38: =IFERROR(INDEX(SORTBY(FILTER(ETF_Master!A:AK,ETF_Master!D:D="Thematic Growth"),FILTER(ETF_Master!AI:AI,ETF_Master!D:D="Thematic Growth"),-1),ROW(A1),{1,3,4,6,35,36,37}),"")
A41: Top 5 Difensivi
A42: Rank | B42: Ticker | C42: Nome ETF | D42: Categoria | E42: Tema | F42: Score | G42: Stato | H42: Note AI
A43: {=SEQUENCE(5)} | B43: =IFERROR(INDEX(SORTBY(FILTER(ETF_Master!A:AK,ETF_Master!D:D="Defensive"),FILTER(ETF_Master!AI:AI,ETF_Master!D:D="Defensive"),-1),ROW(A1),{1,3,4,6,35,36,37}),"")
A44: 2 | B44: =IFERROR(INDEX(SORTBY(FILTER(ETF_Master!A:AK,ETF_Master!D:D="Defensive"),FILTER(ETF_Master!AI:AI,ETF_Master!D:D="Defensive"),-1),ROW(A1),{1,3,4,6,35,36,37}),"")
A45: 3 | B45: =IFERROR(INDEX(SORTBY(FILTER(ETF_Master!A:AK,ETF_Master!D:D="Defensive"),FILTER(ETF_Master!AI:AI,ETF_Master!D:D="Defensive"),-1),ROW(A1),{1,3,4,6,35,36,37}),"")
A46: 4 | B46: =IFERROR(INDEX(SORTBY(FILTER(ETF_Master!A:AK,ETF_Master!D:D="Defensive"),FILTER(ETF_Master!AI:AI,ETF_Master!D:D="Defensive"),-1),ROW(A1),{1,3,4,6,35,36,37}),"")
A47: 5 | B47: =IFERROR(INDEX(SORTBY(FILTER(ETF_Master!A:AK,ETF_Master!D:D="Defensive"),FILTER(ETF_Master!AI:AI,ETF_Master!D:D="Defensive"),-1),ROW(A1),{1,3,4,6,35,36,37}),"")
A50: Alert macro/geopolitici e note AI
...

Sheet Sources
A1: Fonte | B1: Uso | C1: URL | D1: Note
A2: Borsa Italiana ETFplus | B2: Elenco ETF, dati ufficiali | C2: https://www.borsaitaliana.it/etf/etf/home.htm | D2: Fonte ufficiale per universo italiano
A3: justETF | B3: TER, replica, distribuzione, AUM | C3: https://www.justetf.com/it/ | D3: Utile per dati ETF UCITS
A4: Yahoo Finance / yfinance | B4: Prezzi storici prototipo | C4: https://finance.yahoo.com/ | D4: Da verificare ticker e qualità dati
A5: ECB | B5: Tassi e macro Eurozona | C5: https://www.ecb.europa.eu/ | D5: Macro engine
A6: FRED | B6: Dati macro USA | C6: https://fred.stlouisfed.org/ | D6: Tassi, inflazione, spread
A7: IMF | B7: Scenario macro globale | C7: https://www.imf.org/ | D7: Contesto globale
